from traceback import print_exception

from fastapi import FastAPI, HTTPException
from models import (
    funcionario_models, departamento_models, empresa_models, cliente_models, contrato_models, projeto_models
)
from controllers import (
    departamentos_controller, empresas_controller, funcionarios_controller, clientes_controller, contratos_controller, projetos_controller
)

# Resolver referÃªncias dos modelos
funcionario_models.FuncionarioDetalhadoDTO.resolve_refs()
departamento_models.DepartamentoDetalhadoDTO.resolve_refs()
empresa_models.EmpresaDetalhadaDTO.resolve_refs()
cliente_models.ClienteDetalhadoDTO.resolve_refs()
contrato_models.ContratoDetalhadoDTO.resolve_refs()
projeto_models.ProjetoDetalhadoDTO.resolve_refs()

app = FastAPI()

try:
    app.include_router(departamentos_controller.router)
    app.include_router(empresas_controller.router)
    app.include_router(funcionarios_controller.router)
    app.include_router(clientes_controller.router)
    app.include_router(contratos_controller.router)
    app.include_router(projetos_controller.router)
except Exception as e:
    print_exception(e)
    raise HTTPException(status_code=500, detail="Erro interno do servidor")